from passlib.context import CryptContext
from jose import JWTError, jwt
from datetime import datetime, timedelta
from fastapi import HTTPException, status
from sqlalchemy.orm import Session
import schemas, models
import os
from typing import Optional

# Настройки безопасности
SECRET_KEY = os.environ.get("SECRET_KEY", "your-secret-key-for-development")
ALGORITHM = "HS256"
ACCESS_TOKEN_EXPIRE_MINUTES = 30

# Для хеширования паролей
pwd_context = CryptContext(schemes=["bcrypt"], deprecated="auto")

def verify_password(plain_password, hashed_password):
    return pwd_context.verify(plain_password, hashed_password)

def get_password_hash(password):
    return pwd_context.hash(password)

def authenticate_user(db: Session, username: str, password: str):
    user = db.query(models.User).filter(models.User.username == username).first()
    if not user:
        return False
    if not verify_password(password, user.hashed_password):
        return False
    return user

def create_access_token(data: dict, expires_delta: Optional[timedelta] = None):
    to_encode = data.copy()
    if expires_delta:
        expire = datetime.utcnow() + expires_delta
    else:
        expire = datetime.utcnow() + timedelta(minutes=15)
    to_encode.update({"exp": expire})
    encoded_jwt = jwt.encode(to_encode, SECRET_KEY, algorithm=ALGORITHM)
    return encoded_jwt

def get_current_user(db: Session, token: str):
    credentials_exception = HTTPException(
        status_code=status.HTTP_401_UNAUTHORIZED,
        detail="Could not validate credentials",
        headers={"WWW-Authenticate": "Bearer"},
    )
    try:
        payload = jwt.decode(token, SECRET_KEY, algorithms=[ALGORITHM])
        username: str = payload.get("sub")
        if username is None:
            raise credentials_exception
        token_data = schemas.TokenData(username=username)
    except JWTError:
        raise credentials_exception
    user = db.query(models.User).filter(models.User.username == token_data.username).first()
    if user is None:
        raise credentials_exception
    return user
